<?xml version="1.0"?>
<robot name="triangle">

  <link name="world0">
  </link>

  <link name="world1">
  </link>

  <link name="world2">
  </link>

  <link name="triangle">
    <visual>
      <origin xyz="0.0 0.0 0.0"/>
      <geometry>
        <mesh filename="EquivDP/triangle.obj" scale="0.1 0.1 0.1"/>
      </geometry>
    </visual>
    <collision>
      <origin xyz="0.0 0.0 0.0"/>
      <geometry>
        <mesh filename="EquivDP/triangle.obj" scale="0.1 0.1 0.1"/>
      </geometry>
    </collision>
    <inertial>
      <mass value="0.068"/>
      <inertia ixx="0.0001" ixy="0.0" ixz="0.0" iyy="0.0001" iyz="0.0" izz="0.0001"/>
    </inertial>
  </link>

  <joint name="trans_x" type="prismatic">
    <parent link="world0"/>
    <child link="world1"/>
    <origin xyz="0.0 0.0 0.0"/>
    <axis xyz="1 0 0"/>
    <limit effort="1000.0" lower="-0.3" upper="0.3" velocity="100"/>
  </joint>

  <joint name="trans_z" type="prismatic">
    <parent link="world1"/>
    <child link="world2"/>
    <origin xyz="0.0 0.0 0.0"/>
    <axis xyz="0 0 1"/>
    <limit effort="1000.0" lower="-0.5" upper="0.5" velocity="100"/>
  </joint>

  <joint name="rot_y" type="revolute">
    <axis xyz="0 1 0"/>
    <origin xyz="0 0 0"/>
    <parent link="world2"/>
    <child link="triangle"/>
    <limit effort="1000.0" velocity="8"/>
  </joint>

</robot>
